Workbook
Name Excel_BuiltIn__FilterDatabase: ELENCO!$B$1:$C$1
Name Excel_BuiltIn__FilterDatabase_1_1: #REF!
Name Excel_BuiltIn__FilterDatabase_10: "$#RIF!.$B$1:$AH$289"
Name Excel_BuiltIn__FilterDatabase_10_1: ELENCO!$B$1:$AH$143
Name Excel_BuiltIn_Print_Area: SITREP!$A$1:$V$45
Name Excel_BuiltIn_Print_Area_1_1: #REF!
Name Excel_BuiltIn_Print_Area_1_1_1: "$#RIF!.$A$1:$K$257"
Name Excel_BuiltIn_Print_Area_10: "$#RIF!.$A$1:$BL$212"
Name Excel_BuiltIn_Print_Area_12: "$#RIF!.$A$1:$Q$83"
Name Excel_BuiltIn_Print_Area_13: "$#RIF!.$A$47:$E$114"
Name Excel_BuiltIn_Print_Area_3_1: #REF!
Name Excel_BuiltIn_Print_Area_3_1_1: #REF!
Name Excel_BuiltIn_Print_Area_3_1_1_1: SIESTAT_1_!$A$1:$Y$52
Name Excel_BuiltIn_Print_Area_4_1: #REF!
Name Excel_BuiltIn_Print_Area_4_1_1: SIESTAT_1_!$A$1:$Y$51
Name Excel_BuiltIn_Print_Area_5_1: #REF!
Name Excel_BuiltIn_Print_Area_5_1_1: #REF!
Name Excel_BuiltIn_Print_Area_6_1: #REF!
Name Excel_BuiltIn_Print_Area_6_1_1: "$ELENCO.$#RIF!$#RIF!:$#RIF!$#RIF!"
Name Excel_BuiltIn_Print_Area_7_1: #REF!
Name Excel_BuiltIn_Print_Area_7_1_1: #REF!
Name Excel_BuiltIn_Print_Area_7_1_1_1: "$#RIF!.$A$2:$I$24"
Name Excel_BuiltIn_Print_Area_9: "$#RIF!.$A$1:$I$257"
Name PRESENTE: "$#RIF!.$F$264"

Sheet SIESTAT_1_
D1: 11° REGGIMENTO TRASMISSIONI
B2: BATTAGLIONE TRASMISSIONI "TONALE"
C3: 1^ Compagnia
C4: =#REF! -> #REF!
A6: GRADO / ANZIANITA' | B6: RUOLO / ARMA | C6: Effettivi | D6: Assenti | E6: PRESENTI | F6: 1 | G6: 2 | H6: 3 | I6: 4 | J6: 5 | K6: 6 | L6: 7 | M6: 8 | N6: 9 | O6: 10 | P6: 11 | Q6: 12 | R6: 13 | S6: 14 | T6: 15 | U6: 16 | V6: 17 | W6: 18 | X6: 19 | Y6: 20 | Z6: TOTALE
A7: Colonnello / - | B7: Ruolo Normale / Armi Varie | D7: =SUM(F7:Y7)+'SIESTAT 2'!AC5 -> 0 | E7: =C7-D7 -> 0 | Z7: =SUM(F7:Y7) -> 0
A8: Tenente Colonnello / +15 | B8: Ruolo Normale / Armi Varie | C8: =#REF! -> #REF! | D8: =SUM(F8:Y8)+'SIESTAT 2'!AC6 -> #REF! | E8: =C8-D8 -> #REF! | H8: =ELENCO!H28 -> 1 | J8: =#REF! -> #REF! | Q8: =#REF!+#REF! -> #REF! | T8: =#REF!+#REF! -> #REF! | U8: =#REF!+#REF! -> #REF! | V8: =#REF! -> #REF! | Y8: =#REF! -> #REF! | Z8: =SUM(F8:Y8) -> #REF!
A9: Tenente Colonnello / +15 | B9: Ruolo Speciale / Armi Varie | D9: =SUM(F9:Y9)+'SIESTAT 2'!AC7 -> 0 | E9: =C9-D9 -> 0 | Z9: =SUM(F9:Y9) -> 0
A10: Tenente Colonnello / +15 | B10: Ruolo Normale / Corpo Sanitario | D10: =SUM(F10:Y10)+'SIESTAT 2'!AC8 -> 0 | E10: =C10-D10 -> 0 | Z10: =SUM(F10:Y10) -> 0
A11: Tenente Colonnello / +15 | B11: Ruolo Speciale / Arma dei Trasporti e Materiali | D11: =SUM(F11:Y11)+'SIESTAT 2'!AC9 -> 0 | E11: =C11-D11 -> 0 | Z11: =SUM(F11:Y11) -> 0
A12: Maggiore / +25 | B12: Ruolo Tecnico Amministrativo / Armi varie | D12: =SUM(F12:Y12)+'SIESTAT 2'!AC10 -> 0 | E12: =C12-D12 -> 0 | Z12: =SUM(F12:Y12) -> 0
A13: Maggiore / +25 | B13: Ruolo Tecnico Amministrativo / Arma dei Trasporti e Materiali | D13: =SUM(F13:Y13)+'SIESTAT 2'!AC11 -> 0 | E13: =C13-D13 -> 0 | Z13: =SUM(F13:Y13) -> 0
A14: Maggiore / +15 | B14: Ruolo Speciale / Armi Varie | D14: =SUM(F14:Y14)+'SIESTAT 2'!AC12 -> 0 | E14: =C14-D14 -> 0 | Z14: =SUM(F14:Y14) -> 0
A15: Maggiore / +15 | B15: Ruolo normale / Armi Varie | D15: =SUM(F15:Y15)+'SIESTAT 2'!AC13 -> 0 | E15: =C15-D15 -> 0 | Z15: =SUM(F15:Y15) -> 0
A16: Capitano / +25 | B16: Ruolo Tecnico Amministrativo / Armi Varie | D16: =SUM(F16:Y16)+'SIESTAT 2'!AC14 -> 0 | E16: =C16-D16 -> 0 | Z16: =SUM(F16:Y16) -> 0
A17: Capitano / +13 | B17: Ruolo Normale / Armi Varie | D17: =SUM(F17:Y17)+'SIESTAT 2'!AC15 -> 0 | E17: =C17-D17 -> 0 | Z17: =SUM(F17:Y17) -> 0
A18: Capitano / +13 | B18: Ruolo Speciale / Armi Varie | D18: =SUM(F18:Y18)+'SIESTAT 2'!AC16 -> 0 | E18: =C18-D18 -> 0 | Z18: =SUM(F18:Y18) -> 0
A19: Capitano / +13 | B19: Ruolo Tecnico Amministrativo / Armi Varie | D19: =SUM(F19:Y19)+'SIESTAT 2'!AC17 -> 0 | E19: =C19-D19 -> 0 | Z19: =SUM(F19:Y19) -> 0
A20: capitano /-13 | B20: ruolo normale / armi varie | C20: =#REF! -> #REF! | D20: =SUM(F20:Y20)+'SIESTAT 2'!AC18 -> #REF! | E20: =C20-D20 -> #REF! | F20: =#REF! -> #REF! | H20: =ELENCO!H30 -> 0 | J20: =#REF! -> #REF! | Q20: =#REF!+#REF! -> #REF! | T20: =#REF!+#REF! -> #REF! | U20: =#REF!+#REF! -> #REF! | V20: =#REF! -> #REF! | Y20: =#REF! -> #REF! | Z20: =SUM(F20:Y20) -> #REF!
A21: capitano / -13 | B21: Ruolo Tecnico Amministrativo / Armi Varie | D21: =SUM(F21:Y21)+'SIESTAT 2'!AC19 -> 0 | E21: =C21-D21 -> 0 | Z21: =SUM(F21:Y21) -> 0
A22: Tenente / +13 | B22: Ruolo Speciale / Armi Varie | D22: =SUM(F22:Y22)+'SIESTAT 2'!AC20 -> 0 | E22: =C22-D22 -> 0 | Z22: =SUM(F22:Y22) -> 0
A23: Tenente / -13 | B23: Ruolo Normale / Armi Varie | C23: =#REF! -> #REF! | D23: =SUM(F23:Y23)+'SIESTAT 2'!AC21 -> #REF! | E23: =C23-D23 -> #REF! | F23: =#REF! -> #REF! | H23: =ELENCO!H31 -> 0 | J23: =#REF! -> #REF! | Q23: =#REF!+#REF! -> #REF! | T23: =#REF!+#REF! -> #REF! | U23: =#REF!+#REF! -> #REF! | V23: =#REF! -> #REF! | Y23: =#REF! -> #REF! | Z23: =SUM(F23:Y23) -> #REF!
A24: Tenente / -13 | B24: Ruolo Speciale / Armi Varie | D24: =SUM(F24:Y24)+'SIESTAT 2'!AC22 -> 0 | E24: =C24-D24 -> 0 | Z24: =SUM(F24:Y24) -> 0
A25: Tenente / -13 | B25: Ruolo Normale / Corpo degli Ingegneri | D25: =SUM(F25:Y25)+'SIESTAT 2'!AC23 -> 0 | E25: =C25-D25 -> 0 | Z25: =SUM(F25:Y25) -> 0
A26: Tenente / -13 | B26: Ruolo Speciale / Arma dei Trasporti e Materiali | D26: =SUM(F26:Y26)+'SIESTAT 2'!AC24 -> 0 | E26: =C26-D26 -> 0 | Z26: =SUM(F26:Y26) -> 0
A27: Sottotenente / - | B27: Ruolo Speciale / Armi Varie | C27: =#REF! -> #REF! | D27: =SUM(F27:Y27)+'SIESTAT 2'!AC25 -> #REF! | E27: =C27-D27 -> #REF! | H27: =#REF! -> #REF! | J27: =#REF! -> #REF! | Q27: =#REF!+#REF! -> #REF! | T27: =#REF!+#REF! -> #REF! | U27: =#REF!+#REF! -> #REF! | V27: =#REF! -> #REF! | Y27: =#REF! -> #REF! | Z27: =SUM(F27:Y27) -> #REF!
A28: Luogotenente / - | B28: Ruolo Marescialli / - | C28: =#REF! -> #REF! | D28: =SUM(F28:Y28)+'SIESTAT 2'!AC26 -> #REF! | E28: =C28-D28 -> #REF! | H28: =ELENCO!H33 -> 0 | J28: =#REF! -> #REF! | Q28: =#REF!+#REF! -> #REF! | T28: =#REF!+#REF! -> #REF! | U28: =#REF!+#REF! -> #REF! | V28: =#REF! -> #REF! | Y28: =#REF! -> #REF! | Z28: =SUM(F28:Y28) -> #REF!
A29: Primo Maresciallo / - | B29: Ruolo Marescialli / - | C29: =#REF! -> #REF! | D29: =SUM(F29:Y29)+'SIESTAT 2'!AC27 -> #REF! | E29: =C29-D29 -> #REF! | H29: =ELENCO!H35 -> 0 | J29: =#REF! -> #REF! | Q29: =#REF!+#REF! -> #REF! | T29: =#REF!+#REF! -> #REF! | U29: =#REF!+#REF! -> #REF! | V29: =#REF! -> #REF! | Y29: =#REF! -> #REF! | Z29: =SUM(F29:Y29) -> #REF!
A30: Maresciallo Capo / - | B30: Ruolo Marescialli / - | C30: =#REF! -> #REF! | D30: =SUM(F30:Y30)+'SIESTAT 2'!AC28 -> #REF! | E30: =C30-D30 -> #REF! | F30: =#REF! -> #REF! | H30: =ELENCO!H36 -> 0 | J30: =#REF! -> #REF! | Q30: =#REF!+#REF! -> #REF! | T30: =#REF!+#REF! -> #REF! | U30: =#REF!+#REF! -> #REF! | V30: =#REF! -> #REF! | Y30: =#REF! -> #REF! | Z30: =SUM(F30:Y30) -> #REF!
A31: Maresciallo Ordinario / +10 | B31: Ruolo Marescialli / - | C31: =#REF! -> #REF! | D31: =SUM(F31:Y31)+'SIESTAT 2'!AC29 -> #REF! | E31: =C31-D31 -> #REF! | H31: =ELENCO!H37 -> 0 | J31: =#REF! -> #REF! | Q31: =#REF!+#REF! -> #REF! | T31: =#REF!+#REF! -> #REF! | U31: =#REF!+#REF! -> #REF! | V31: =#REF! -> #REF! | Y31: =#REF! -> #REF! | Z31: =SUM(F31:Y31) -> #REF!
A32: Maresciallo / - | B32: Ruolo Marescialli / - | C32: =#REF! -> #REF! | D32: =SUM(F32:Y32)+'SIESTAT 2'!AC30 -> #REF! | E32: =C32-D32 -> #REF! | F32: =#REF! -> #REF! | H32: =ELENCO!H38 -> 0 | J32: =#REF! -> #REF! | Q32: =#REF!+#REF! -> #REF! | T32: =#REF!+#REF! -> #REF! | U32: =#REF!+#REF! -> #REF! | V32: =#REF! -> #REF! | Y32: =#REF! -> #REF! | Z32: =SUM(F32:Y32) -> #REF!
A33: Sergente Maggiore / - | B33: Ruolo Sergenti / - | C33: =#REF! -> #REF! | D33: =SUM(F33:Y33)+'SIESTAT 2'!AC31 -> #REF! | E33: =C33-D33 -> #REF! | F33: =#REF! -> #REF! | H33: =ELENCO!H41 -> 1 | J33: =#REF! -> #REF! | Q33: =#REF!+#REF! -> #REF! | T33: =#REF!+#REF! -> #REF! | U33: =#REF!+#REF! -> #REF! | V33: =#REF! -> #REF! | Y33: =#REF! -> #REF! | Z33: =SUM(F33:Y33) -> #REF!
A34: Sergente / - | B34: Ruolo Sergenti / - | C34: =#REF! -> #REF! | D34: =SUM(F34:Y34)+'SIESTAT 2'!AC32 -> #REF! | E34: =C34-D34 -> #REF! | F34: =#REF! -> #REF! | H34: =ELENCO!H42 -> 0 | J34: =#REF! -> #REF! | Q34: =#REF!+#REF! -> #REF! | T34: =#REF!+#REF! -> #REF! | U34: =#REF!+#REF! -> #REF! | V34: =#REF! -> #REF! | Y34: =#REF! -> #REF! | Z34: =SUM(F34:Y34) -> #REF!
A35: Caporal maggiore capo / - | B35: - / - | C35: =#REF! -> #REF! | D35: =SUM(F35:Y35)+'SIESTAT 2'!AC33 -> #REF! | E35: =C35-D35 -> #REF! | F35: =#REF! -> #REF! | H35: =ELENCO!H45 -> 3 | J35: =#REF! -> #REF! | Q35: =#REF!+#REF! -> #REF! | T35: =#REF!+#REF! -> #REF! | U35: =#REF!+#REF! -> #REF! | V35: =#REF! -> #REF! | Y35: =#REF! -> #REF! | Z35: =SUM(F35:Y35) -> #REF!
A36: Caporal maggiore scelto / - | B36: - / - | C36: =#REF! -> #REF! | D36: =SUM(F36:Y36)+'SIESTAT 2'!AC34 -> #REF! | E36: =C36-D36 -> #REF! | F36: =ELENCO!P46 -> 0 | H36: =ELENCO!H46 -> 2 | J36: =#REF! -> #REF! | Q36: =#REF!+#REF! -> #REF! | T36: =#REF!+#REF! -> #REF! | U36: =#REF!+#REF! -> #REF! | V36: =#REF! -> #REF! | Y36: =#REF! -> #REF! | Z36: =SUM(F36:Y36) -> #REF!
A37: 1° Caporal maggiore / - | B37: - / - | C37: =#REF! -> #REF! | D37: =SUM(F37:Y37)+'SIESTAT 2'!AC35 -> #REF! | E37: =C37-D37 -> #REF! | F37: =ELENCO!P47 -> 0 | H37: =ELENCO!H47 -> 0 | J37: =#REF! -> #REF! | Q37: =#REF!+#REF! -> #REF! | T37: =#REF!+#REF! -> #REF! | U37: =#REF!+#REF! -> #REF! | V37: =#REF! -> #REF! | Y37: =#REF! -> #REF! | Z37: =SUM(F37:Y37) -> #REF!
A38: Volontario in ferma prefissata - VFP4 / - | B38: - / - | C38: =#REF!+#REF! -> #REF! | D38: =SUM(F38:Y38)+'SIESTAT 2'!AC36 -> #REF! | E38: =C38-D38 -> #REF! | F38: =ELENCO!P50 -> 0 | H38: =ELENCO!H49+ELENCO!H50 -> 0 | J38: =#REF!+#REF! -> #REF! | Q38: =#REF!+#REF!+#REF!+#REF! -> #REF! | T38: =#REF!+#REF!+#REF!+#REF! -> #REF! | U38: =#REF!+#REF!+#REF!+#REF! -> #REF! | V38: =#REF!+M46 -> #REF! | Y38: =#REF!+#REF! -> #REF! | Z38: =SUM(F38:Y38) -> #REF!
A39: Volontario in ferma breve / - | B39: - / - | C39: =#REF! -> #REF! | D39: =SUM(F39:Y39)+'SIESTAT 2'!AC37 -> #REF! | E39: =C39-D39 -> #REF! | F39: =ELENCO!P47+ELENCO!P48 -> 0 | H39: =ELENCO!H47 -> 0 | J39: =#REF!+#REF! -> #REF! | Q39: =#REF!+#REF!+#REF!+#REF! -> #REF! | T39: =#REF!+#REF! -> #REF! | U39: =SUM(#REF!) -> #REF! | V39: =#REF!+#REF! -> #REF! | Y39: =#REF!+#REF! -> #REF! | Z39: =SUM(F39:Y39) -> #REF!
A40: V.F.B. raffermato / - (1° C.le Magg.) | B40: - / - | C40: =#REF! -> #REF! | D40: =SUM(F40:Y40)+'SIESTAT 2'!AC38 -> 8 | E40: =C40-D40 -> #REF! | H40: =ELENCO!H49 -> 0 | J40: =ELENCO!K48 -> 0 | Q40: =ELENCO!I49 -> 5 | T40: =ELENCO!M48+ELENCO!N48 -> 0 | U40: =ELENCO!J48+ELENCO!L48 -> 0 | V40: =ELENCO!F49 -> 0 | Y40: =ELENCO!R48 -> 0 | Z40: =SUM(F40:Y40) -> 5
A41: Volontario in ferma prefissata - VFP1 / - | B41: - / - | C41: =#REF! -> #REF! | D41: =SUM(F41:Y41)+'SIESTAT 2'!AC39 -> #REF! | E41: =C41-D41 -> #REF! | H41: =ELENCO!H51 -> 2 | J41: =#REF! -> #REF! | Q41: =#REF!+#REF!+#REF!+#REF! -> #REF! | T41: =#REF!+#REF! -> #REF! | U41: =#REF!+#REF!+#REF!+#REF! -> #REF! | V41: =#REF! -> #REF! | Y41: =#REF!+#REF! -> #REF! | Z41: =SUM(F41:Y41) -> #REF!
...

Sheet SIESTAT 2
A1: 11° REGGIMENTO TRASMISSIONI
A2: BATTAGLIONE TRASMISSIONI “TONALE”
A3: 1^ COMPAGNIA
A4: GRADO / ANZIANITA' | B4: RUOLO / ARMA | C4: AFGHANISTAN | D4: ALBANIA | E4: BOSNIA | F4: CONGO | G4: AFGHANISTAN | H4: AFGHANISTAN | I4: EGITTO | J4: FYROM | K4: GAZA | L4: GIORDANIA | M4: GRAN BRETAGNA | N4: IRAQ | O4: KOSOVO | P4: LIBANO | Q4: SUDAN DARFUR | R4: U.S.A. | S4: U.S.A. | T4: U.S.A. | U4: U.S.A. | V4: U.S.A. | W4: U.S.A. | X4: U.S.A. | Y4: U.S.A. | Z4: U.S.A. | AA4: U.S.A. | AB4: U.S.A. | AC4: TOTALE
A5: Colonnello / - | B5: Ruolo Normale / Armi Varie | AC5: =SUM(C5:R5) -> 0
A6: Tenente Colonnello / +15 | B6: Ruolo Normale / Armi Varie | O6: 1 | AC6: =SUM(C6:R6) -> 1
A7: Tenente Colonnello / +15 | B7: Ruolo Speciale / Armi Varie | AC7: =SUM(C7:R7) -> 0
A8: Tenente Colonnello / +15 | B8: Ruolo Normale / Corpo Sanitario | AC8: =SUM(C8:R8) -> 0
A9: Tenente Colonnello / +15 | B9: Ruolo Speciale / Arma dei Trasporti e Materiali | AC9: =SUM(C9:R9) -> 0
A10: Maggiore / +25 | B10: Ruolo Tecnico Amministrativo / Armi varie | AC10: =SUM(C10:R10) -> 0
A11: Maggiore / +25 | B11: Ruolo Tecnico Amministrativo / Arma dei Trasporti e Materiali | AC11: =SUM(C11:R11) -> 0
A12: Maggiore / +15 | B12: Ruolo Speciale / Armi Varie | AC12: =SUM(C12:R12) -> 0
A13: Maggiore / +15 | B13: Ruolo normale / Armi Varie | AC13: =SUM(C13:R13) -> 0
A14: Capitano / +25 | B14: Ruolo Tecnico Amministrativo / Armi Varie | AC14: =SUM(C14:R14) -> 0
A15: Capitano / +13 | B15: Ruolo Normale / Armi Varie | AC15: =SUM(C15:R15) -> 0
A16: Capitano / +13 | B16: Ruolo Speciale / Armi Varie | AC16: =SUM(C16:R16) -> 0
A17: Capitano / +13 | B17: Ruolo Tecnico Amministrativo / Armi Varie | AC17: =SUM(C17:R17) -> 0
A18: capitano /-13 | B18: ruolo normale / armi varie | AC18: =SUM(C18:R18) -> 0
... A20: Tenente / +13 | B20: Ruolo Speciale / Armi Varie | AC20: =SUM(C20:R20) -> 0
A21: Tenente / -13 | B21: Ruolo Normale / Armi Varie | O21: 2 | AC21: =SUM(C21:R21) -> 2
A22: Tenente / -13 | B22: Ruolo Speciale / Armi Varie | AC22: =SUM(C22:R22) -> 0
A23: Tenente / -13 | B23: Ruolo Normale / Corpo degli Ingegneri | AC23: =SUM(C23:R23) -> 0
A24: Tenente / -13 | B24: Ruolo Speciale / Arma dei Trasporti e Materiali | AC24: =SUM(C24:R24) -> 0
A25: Sottotenente / - | B25: Ruolo Speciale / Armi Varie | AC25: =SUM(C25:R25) -> 0
A26: Luogotenente / - | B26: Ruolo Marescialli / - | O26: 1 | AC26: =SUM(C26:R26) -> 1
A27: Primo Maresciallo / - | B27: Ruolo Marescialli / - | C27: 1 | O27: 1 | AC27: =SUM(C27:R27) -> 2
A28: Maresciallo Capo / - | B28: Ruolo Marescialli / - | AC28: =SUM(C28:R28) -> 0
A29: Maresciallo Ordinario / +10 | B29: Ruolo Marescialli / - | AC29: =SUM(C29:R29) -> 0
A30: Maresciallo / - | B30: Ruolo Marescialli / - | AC30: =SUM(C30:R30) -> 0
A31: Sergente Maggiore / - | B31: Ruolo Sergenti / - | AC31: =SUM(C31:R31) -> 0
A32: Sergente / - | B32: Ruolo Sergenti / - | C32: 1 | O32: 2 | AC32: =SUM(C32:R32) -> 3
A33: Caporal maggiore capo / - | B33: - / - | O33: 2 | AC33: =SUM(C33:R33) -> 2
A34: Caporal maggiore scelto / - | B34: - / - | C34: 2 | O34: 4 | AC34: =SUM(C34:R34) -> 6
A35: 1° Caporal maggiore / - | B35: - / - | C35: 1 | O35: 2 | AC35: =SUM(C35:R35) -> 3
A36: Volontario in ferma prefissata - VFP4 / - | B36: - / - | O36: 1 | AC36: =SUM(C36:R36) -> 1
A37: Volontario in ferma breve / - | B37: - / - | O37: 8 | AC37: =SUM(C37:R37) -> 8
A38: V.F.B. raffermato (grado 1° C.le Magg.) | O38: 3 | AC38: =SUM(C38:R38) -> 3
A39: Volontario in ferma prefissata - VFP1 / - | B39: - / - | AC39: =SUM(C39:R39) -> 0
A40: Posiz. Econ. B2 / - | B40: - / - | AC40: =SUM(C40:R40) -> 0
A41: TOTALE | C41: =SUM(C5:C40) -> 5 | D41: =SUM(D5:D40) -> 0 | E41: =SUM(E5:E40) -> 0 | F41: =SUM(F5:F40) -> 0 | I41: =SUM(I5:I40) -> 0 | J41: =SUM(J5:J40) -> 0 | K41: =SUM(K5:K40) -> 0 | L41: =SUM(L5:L40) -> 0 | M41: =SUM(M5:M40) -> 0 | N41: =SUM(N5:N40) -> 0 | O41: =SUM(O5:O40) -> 27 | P41: =SUM(P5:P40) -> 0 | ... AC41: =SUM(AC5:AC40) -> 32
...

Sheet SITREP

Sheet Sheet8

Sheet Sheet9

Sheet Sheet10

Sheet ELENCO
A1: N | B1: Gradi | C1: Cognome e Nome | E1: FORZA EFFETTIVA | T1: CIVILI
A2: 1 | B2: Ten.Col. | C2: di CAMILLO Dora | E2: UOMINI | F2: DONNE | G2: UOMINI | H2: DONNE | I2: UOMINI | J2: DONNE | K2: UOMINI | L2: DONNE | M2: UOMINI | N2: DONNE | O2: UOMINI | P2: DONNE | Q2: UOMINI | R2: DONNE | T2: EFF | U2: ASSENTI | V2: PRESENTI
A3: 2 | B3: Cap. | C3: CACCAMO Mattia | E3: TRS | F3: TRS | G3: C.LI VFP1 | H3: C.LI VFP1 | I3: C.LIVFP4 | J3: C.LIVFP4 | K3: C.M. VFP4 | L3: C.M. VFP4 | M3: PCM (VFP4) | N3: PCM (VFP4) | Q3: CIVILI | R3: CIVILI | T3: =Q5+R5 -> 0 | U3: =T52 -> 0 | V3: =T3-U3 -> 0
A4: 3 | B4: Cap. | C4: CORRADO Mariano Benito | T4: VFP1
A5: 4 | B5: Ten. | C5: DI GENNARO Michele | E5: 20 | F5: 6 | I5: 3 | J5: 3 | K5: 8 | L5: 4 | T5: EFF | U5: ASSENTI | V5: PRESENTI
A6: 5 | B6: 1°Lgt. | C6: CERICA Alberto | E6: Grd | F6: Grd | G6: Grd. sc | H6: Grd. sc | I6: Grd. ca | J6: Grd. ca | K6: 1°Grd. | L6: 1°Grd. | M6: Grd. A. | N6: Grd. A. | O6: SERG | P6: SERG | Q6: Serg. Magg | R6: Serg. Magg | T6: =SUM(G5+H5+E5+F5) -> 26 | U6: =T51 -> 6 | V6: =T6-U6 -> 20
A7: 6 | B7: 1°Lgt. | C7: CANENSI Alessandro | U7: VFP4
A8: 7 | B8: Mar.Ord. | C8: MALATESTA Salvatore | E8: 10 | F8: 2 | G8: 14 | H8: 3 | I8: 12 | J8: 1 | K8: 12 | L8: 1 | M8: 14 | O8: 1 | Q8: 8 | T8: EFF | U8: ASSENTI | V8: PRESENTI
A9: 8 | B9: Serg. Magg. Aiut. | C9: BUONANNO Francesco | E9: S.M.C | F9: S.M.C | G9: S.M.A. | H9: S.M.A. | I9: MAR | J9: MAR | K9: M.O. | L9: M.O. | M9: M.C. | N9: M.C. | O9: Primo Mar | P9: Primo Mar | Q9: Lgt | R9: Lgt | T9: =I5+J5+K5+L5 -> 18 | U9: =SUM(T49:T50) -> 11 | V9: =T9-U9 -> 7
A10: 9 | B10: Serg. Magg. Aiut. | C10: CARDONE Gianfranco
A11: 10 | B11: Serg. Magg. Aiut. | C11: PETROSELLI Maurizio | T11: PCM VFP4
A12: 11 | B12: Serg. Magg. Ca. | C12: TARANTINO Angelo | E12: 5 | G12: 3 | K12: 1 | T12: EFF | U12: ASSENTI | V12: PRESENTI
A13: 12 | B13: Serg. Magg. Ca. | C13: SALERNITANO Mario | E13: Primo LGT | F13: Pr imoLgt | G13: S.TEN | H13: S.TEN | I13: TEN | J13: TEN | K13: CAPITANO | L13: CAPITANO | M13: MAGG | N13: MAGG | O13: TEN.COL | P13: TEN.COL | Q13: COL | R13: COL | T13: =M5+N5 -> 0 | U13: =T48 -> 0 | V13: =T13-U13 -> 0
A14: 13 | B14: Serg. Magg. Ca. | C14: ROSSETTI Marco | T14: VSP
A15: 14 | B15: Serg. Magg. Ca. | C15: MONTEFUSCO Alessandro | E15: 2 | I15: 1 | K15: 2 | P15: 1 | T15: EFF | U15: ASSENTI | V15: PRESENTI
A16: 15 | B16: Serg. Magg. Ca. | C16: TORTORA Marco | T16: =E8+F8+G8+H8+I8+J8+K8+L8+M8+N8 -> 69 | U16: =SUM(F43:S47) -> 33 | V16: =T16-U16 -> 36
A17: 16 | B17: Serg. Magg. | C17: DE MARINO Antonio | T17: S.UFF
A18: 17 | B18: Serg. Magg. | C18: LAUDAZI David | E18: EFFETTIVI | F18: =T6+T9+T13+T16+T19+T22+T3 -> 137 | I18: PRESENTI | J18: =V24 -> 73 | M18: ASSENTI | N18: =F18-J18 -> 64 | T18: EFF | U18: ASSENTI | V18: PRESENTI
A19: 18 | B19: Serg. Magg. | C19: CALVANESE Giovanni | T19: =O8+P8+Q8+R8+E12+F12+G12+H12+I12+J12+K12+L12+M12+N12+O12+P12+Q12+R12+E15+F15 -> 20 | U19: =SUM(T33:T42) -> 12 | V19: =T19-U19 -> 8
A20: 19 | B20: Serg. Magg. | C20: MARCELLO Orlando | T20: UFF
A21: 20 | B21: Serg. Magg. | C21: ORLACCHIO Angelo | T21: EFF | U21: ASSENTI | V21: PRESENTI
A22: 21 | B22: Serg. Magg. | C22: AUTIERO Giovanni | T22: =H15+G15+I15+J15+K15+L15+M15+N15+O15+P15+Q15+R15 -> 4 | U22: =SUM(T27:T32) -> 2 | V22: =T22-U22 -> 2
A23: 22 | B23: Serg. Magg. | C23: SILVERI Marco | E23: ASSENZE PER IL RAPPORTINO DEL | H23: 46047
A24: 23 | B24: Serg. Magg. | C24: PERUGINI Maurizio | T24: TOTALE | V24: =SUM(V3:V22) -> 73
A25: 24 | B25: Serg. | C25: PAGANO Vincenzo | E25: GRADI | F25: S.I. | G25: ESTERO | H25: L.O. | I25: L.S. REC | J25: RMD | K25: M.R. | L25: L.CONV. | M25: HC. | N25: HM. | O25: LS104/92 | P25: AGG. V+A | Q25: AGG. V+A FF.A. | R25: FORZA POT ASPETTATIVA' | S25: FIN SETT | T25: TOTALE | U25: AGG DA ALTRI ENTI
A26: 25 | B26: Grd. A. | C26: ARGIOLAS Alessandro
A27: 26 | B27: Grd. A. | C27: CAPORUSCIO Valerio | E27: COL | T27: =SUM(F27:S27) -> 0
A28: 27 | B28: Grd. A. | C28: COSTANZO Sandro | E28: T.COL | H28: 1 | T28: =SUM(F28:S28) -> 1
A29: 28 | B29: Grd. A. | C29: MACCARI Andrea | E29: MAGG | T29: =SUM(F29:S29) -> 0
A30: 29 | B30: Grd. A. | C30: MANTELLINI Domenico | E30: CAP | G30: 1 | T30: =SUM(F30:S30) -> 1
A31: 30 | B31: Grd. A. | C31: NACLERIO Carlo | E31: TEN | T31: =SUM(F31:S31) -> 0
A32: 31 | B32: Grd. A. | C32: ROMANUCCI Luigi | E32: S.TEN | T32: =SUM(F32:S32) -> 0
A33: 32 | B33: Grd. A. | C33: AMOROSO Antonio | E33: Primo LGT | T33: =SUM(F33:S33) -> 0
A34: 33 | B34: Grd. A. | C34: COSTANZO Sossio | E34: Lgt | T34: =SUM(F34:S34) -> 0
A35: 34 | B35: Grd. A. | C35: DI MARIA Giovanni | E35: Primo Mar | T35: =SUM(F35:S35) -> 0
A36: 35 | B36: Grd. A. | C36: SCORDARI Luigi | E36: M.C. | T36: =SUM(F36:S36) -> 0
A37: 36 | B37: Grd. A. | C37: ACCARDO Paolo | E37: M.O. | G37: 1 | T37: =SUM(F37:S37) -> 1
A38: 37 | B38: Grd. A. | C38: PEZZOLLA Fabio | E38: MAR | T38: =SUM(F38:S38) -> 0
A39: 38 | B39: Grd. A. | C39: PIZZO Francesco | E39: SMA | G39: 1 | T39: =SUM(F39:S39) -> 1
A40: 39 | B40: 1°Grd. | C40: FERRARO Davide | E40: SERG.M.C. | G40: 2 | H40: 1 | T40: =SUM(F40:S40) -> 3
...
